2023-08-13 08:54:22.391 ERROR (MainThread) [custom_components.elasticsearch] Error creating initial index/alias: RequestError(400, 'invalid_alias_name_exception', 'Invalid alias name [active-hass-index-v4_1]: an index or data stream exists with the same name as the alias')
Traceback (most recent call last):
  File "/config/custom_components/elasticsearch/es_index_manager.py", line 100, in _create_index_template
    await client.indices.create(
  File "/usr/local/lib/python3.11/site-packages/elasticsearch/_async/client/indices.py", line 123, in create
    return await self.transport.perform_request(
           ^^^^^^^^^^^^^^^^^^^^^^^^^^^^^^^^^^^^^
  File "/usr/local/lib/python3.11/site-packages/elasticsearch/_async/transport.py", line 330, in perform_request
    raise e
  File "/usr/local/lib/python3.11/site-packages/elasticsearch/_async/transport.py", line 297, in perform_request
    status, headers, data = await connection.perform_request(
                            ^^^^^^^^^^^^^^^^^^^^^^^^^^^^^^^^^
  File "/usr/local/lib/python3.11/site-packages/elasticsearch/_async/http_aiohttp.py", line 330, in perform_request
    self._raise_error(response.status, raw_data)
  File "/usr/local/lib/python3.11/site-packages/elasticsearch/connection/base.py", line 322, in _raise_error
    raise HTTP_EXCEPTIONS.get(status_code, TransportError)(
elasticsearch.exceptions.RequestError: RequestError(400, 'invalid_alias_name_exception', 'Invalid alias name [active-hass-index-v4_1]: an index or data stream exists with the same name as the alias')
2023-08-13 08:54:22.413 INFO (MainThread) [custom_components.hacs] <HacsData restore> Restore started
